Workbook

Sheet T1 Summary
A1: F8 (Flair) PBS — UAT Test Cases — Summary
A2: UAT Round 1 • Airline: F8 (Flair) • Generated from product online help • 2026-08-25
A4: Tab | B4: Feature Area | C4: Total Cases | D4: Passed | E4: Failed | F4: Blocked | G4: Not Tested | H4: Pass Rate % | I4: Tested % | J4: Owner | K4: Last Update
A5: T2 Admin UI | B5: Live & Scenario admin gantt | C5: =COUNTIF('T2 Admin UI'!A5:A2000,"T?-*") | D5: =COUNTIF('T2 Admin UI'!G5:G2000,"Pass") | E5: =COUNTIF('T2 Admin UI'!G5:G2000,"Fail") | F5: =COUNTIF('T2 Admin UI'!G5:G2000,"Blocked") | G5: =C5-D5-E5-F5 | H5: =IF(C5=0,"-",(D5)/C5) | I5: =IF(C5=0,"-",(D5+E5+F5)/C5)
A6: T3 Legality | B6: Rule-set legality checks | C6: =COUNTIF('T3 Legality'!A5:A2000,"T?-*") | D6: =COUNTIF('T3 Legality'!G5:G2000,"Pass") | E6: =COUNTIF('T3 Legality'!G5:G2000,"Fail") | F6: =COUNTIF('T3 Legality'!G5:G2000,"Blocked") | G6: =C6-D6-E6-F6 | H6: =IF(C6=0,"-",(D6)/C6) | I6: =IF(C6=0,"-",(D6+E6+F6)/C6)
A7: T4 Crew Portal | B7: Crew bidding portal | C7: =COUNTIF('T4 Crew Portal'!A5:A2000,"T?-*") | D7: =COUNTIF('T4 Crew Portal'!G5:G2000,"Pass") | E7: =COUNTIF('T4 Crew Portal'!G5:G2000,"Fail") | F7: =COUNTIF('T4 Crew Portal'!G5:G2000,"Blocked") | G7: =C7-D7-E7-F7 | H7: =IF(C7=0,"-",(D7)/C7) | I7: =IF(C7=0,"-",(D7+E7+F7)/C7)
A8: TOTAL | B8: All UAT scope | C8: =SUM(C5:C7) | D8: =SUM(D5:D7) | E8: =SUM(E5:E7) | F8: =SUM(F5:F7) | G8: =SUM(G5:G7) | H8: =IF(C8=0,"-",D8/C8) | I8: =IF(C8=0,"-",(D8+E8+F8)/C8)
A10: How to use:
A11: 1. Work top-to-bottom through each tab (T2 Admin UI, T3 Legality, T4 Crew Portal).
A12: 2. Follow the 'How to Test' steps, then set the Result column (Pass / Fail / Blocked / Not Tested).
A13: 3. Add your name in Tester, the date, and any note or screenshot name in Comments.
A14: 4. The Summary tab totals update automatically as you fill in each Result.

Sheet T2 Admin UI
A1: T2 — Admin UI (Live & Scenario)
A2: UAT Round 1 • F8 (Flair) PBS • Reference: online help › Live & Scenario • crew-f8-usva-sit.roiscloud.com/altair
A4: Test ID | B4: Feature | C4: What to Test | D4: How to Test (Steps) | E4: Expected Result | F4: Priority | G4: Result | H4: Tester | I4: Date Tested | J4: Comments / Screenshot | K4: Help Reference
A5: ▸ Live — Roster
A6: T2-LV-001 | B6: Live — Roster | C6: Live opens empty and loads data only after Apply Filters | D6: 1. Open the Live tab. 2. Observe the Gantt canvas and the toolbar next to the filter icon. 3. Click the inline 'No data loaded — apply filters to pull data' reminder to open the Filters dialog. 4. Without setting any filter, click Apply Filters. | E6: On open the Gantt is empty with the inline 'No data loaded — apply filters to pull data' reminder shown next to the filter icon. After Apply Filters the canvas populates with crew rows (each row = one crew member, coloured blocks = assignments); applying with no filter loads the complete schedule. | F6: High | G6: Not Tested | K6: Live › Overview
A7: T2-LV-002 | B7: Live — Roster | C7: Selecting roster periods sets a merged window and requires Apply Filters | D7: 1. Click the roster-period selector (calendar icon reading 'Select RPs'). 2. In the dropdown pick two periods (e.g. 2026RP08 and the next). 3. Read the trigger label and observe the toolbar reminder. 4. Click the RP-changed reminder (or the Filter button) and press Apply Filters. | E7: The trigger shows the merged window on one line (e.g. 2026-07-25 ~ 2026-09-07); before applying, an 'RP Date changed — apply filters to pull data' reminder is shown; the Gantt window equals [earliest start − 7 days, latest end + 7 days]; data loads only after Apply Filters. | F7: Medium | G7: Not Tested | K7: Live › Setting date range
A8: T2-LV-003 | B8: Live — Roster | C8: Roster-period selection is capped at six consecutive periods | D8: 1. Open the roster-period selector dropdown. 2. Select six consecutive periods and read the footer note. 3. Select a seventh period beyond that span. 4. Optionally click the Refresh (circular-arrows ↻) button. | E8: The footer shows 'Max 6 RPs span (performance)'; adding a period beyond six rebuilds a six-period window containing the newly-selected period (never more than six). Refresh reloads the same window with latest crew data and spins while loading. | F8: Medium | G8: Not Tested | K8: Live › Setting date range
A9: T2-LV-004 | B9: Live — Roster | C9: Crew-tab filter reloads canvas and shows filtered/total badge | D9: 1. Click the Filters button in the toolbar. 2. On the Crew tab select a Division (P or C), a Base, and a Rank. 3. Confirm the chosen filters appear as chips in the Active summary bar and the footer shows the active count (e.g. '3 filters active'). 4. Click Apply Filters. | E9: The canvas reloads showing only matching crew; the Filters button turns amber with a count (e.g. 'Filters (3 active)'); the Roster pane title bar shows an amber funnel badge with filtered/total counts (e.g. 12/80). Live allows only one division at a time. | F9: Medium | G9: Not Tested | K9: Live › Filtering crew, pairings, flights
A10: T2-LV-005 | B10: Live — Roster | C10: Pairing ID is a hard filter; Crew ID brings rows to top | D10: 1. Open Filters, go to the Pairing tab, type one or more numeric IDs in Pairing ID (comma/period/space separated), Apply. 2. Observe the Pairing pane. 3. Open Filters, go to the Crew tab, type one or more Crew IDs (comma/period separated) in Crew ID, Apply. 4. Clear both fields and Apply again. | E10: Pairing ID is a hard filter — only those exact pairings remain visible in the Pairing pane. Crew ID does not hide others: the named crew move to the top of the Roster pane (added if not loaded) while everyone else stays below. Clearing the fields and re-applying removes the filters. | F10: Medium | G10: Not Tested | K10: Live › Filtering crew, pairings, flights
A11: T2-LV-006 | B11: Live — Roster | C11: Pane limits enforced and Find Crew by Pairing floats crew to top | D11: 1. Click the Roster pane button twice, the Pairing button twice, and the Flight button once, watching for disabled add buttons. 2. Hover a disabled add button to read its tooltip. 3. In the Pairing pane right-click a flight block and choose Find Crew by Pairing. 4. Click Reset next to the pane buttons. | E11: At most 2 Roster, 2 Pairing, 1 Flight and 4 panes total are allowed; the blocked add button is disabled with a tooltip such as 'Max 2 Roster panes' / 'Max 4 panes'. Find Crew by Pairing floats all crew assigned to that pairing to the top of the matching Roster pane (selected). Reset restores the default one-Roster/one-Pairing layout. | F11: Medium | G11: Not Tested | K11: Live › Working with panes
A12: T2-LV-007 | B12: Live — Roster | C12: Pairing label appears in pane, puck, and Pairing Info title | D12: 1. Open a Pairing pane and read the first 'Pairing' column. 2. Click a pairing row to open the Pairing Info dialog and read its title. 3. Open Filters › Pairing tab, type a label substring in the Label field, Apply. | E12: The Pairing column shows the label for each pairing (falling back to P-{id} when unset); the Pairing Info dialog title leads with the label then the internal id (e.g. 'V4538 #10708'); the Label substring filter shows only pairings whose label contains the entered text. | F12: Medium | G12: Not Tested | K12: Live › Pairing label
A13: T2-LV-008 | B13: Live — Roster | C13: Flight Navi PTNs/Roster/COF columns navigate to pairings, crew, detail | D13: 1. In the Flight pane condition strip click the Navi (compass) button to open the Flight Navi window. 2. Use the smart search box to type a flight number (e.g. 924). 3. Click the PTNs count on a row, then the Roster count, then COF. | E13: Flight Navi opens as a non-modal table of flights in the date range (panes stay live behind it). Clicking PTNs brings that flight's pairings to the top of the Pairing pane; Roster brings its crew to the top of the Roster pane; COF opens the flight's detail card. The window stays open after each click. | F13: Medium | G13: Not Tested | K13: Live › Navigating with Flight Navi
A14: T2-LV-009 | B14: Live — Roster | C14: Reassign a flight duty by dragging to another crew row (draft) | D14: 1. In the Roster pane click a task block to select it (toolbar shows 'N sel'). 2. Drag the block straight up/down onto a different crew member's row and release. 3. Observe the Save button badge. 4. Press Ctrl+S (⌘S on macOS) to save. | E14: The block re-homes to the target crew row; the change is held as a draft and the Save button shows a pending-change count badge; after Ctrl+S the badge clears once saved. Selecting a block shows the 'N sel' count in the toolbar. | F14: High | G14: Not Tested | K14: Live › Editing assignments
A15: T2-LV-010 | B15: Live — Roster | C15: Box-select and Delete removes all pairing segments together | D15: 1. Press on empty space and drag a box across several blocks to box-select them. 2. Right-click one selected block and confirm it reads 'Delete N Tasks'. 3. Choose Delete N Tasks (or press Del/Backspace). 4. Delete a single segment that belongs to a pairing. | E15: Box-select selects every block the box touches; right-click shows 'Delete N Tasks' and removes the whole selection at once. Deleting a block that belongs to a pairing removes all of that crew member's segments of the pairing together, not just the clicked segment. Changes are drafts until saved. | F15: High | G15: Not Tested | K15: Live › Editing assignments
A16: T2-LV-011 | B16: Live — Roster | C16: Roster duty vs row-background right-click menus differ | D16: 1. Right-click a flight task block on a crew row. 2. Note the actions offered. 3. Right-click the empty background of the same crew row (not a block). 4. Note the actions offered. | E16: The flight-duty menu offers Edit Task and Swap Task (ground duty shows Edit Ground Task), plus View pairing detail / Locate Pairing for paired duties, and Schedule Details, Daily Task Calendar, Delete (or Delete N Tasks), Add/Edit Memo. The row-background menu offers Crew Info, Create Ground Task, Add Memo, Schedule Details, Daily Task Calendar, and Manday Info. | F16: Medium | G16: Not Tested | K16: Live › Right-click context menu
A17: T2-LV-012 | B17: Live — Roster | C17: Schedule Details groups a pairing's duties into one summed row | D17: 1. Right-click a crew task block and choose Schedule Details. 2. Verify the title reads 'Schedule Details — {crew ID}' and the RP Date stepper shows one roster period. 3. Read the table columns and the pairing row. 4. Toggle the Timezone control between base timezone and UTC. | E17: The dialog lists columns Type, Start, End, Credit, Label, Pairing, Source; the duties of one pairing appear as a single row spanning earliest start to latest end with credit summed across segments; standalone day-off/ground rows are separate. RP Date shows one period at a time; the Timezone toggle switches Start/End between the crew's base-airport timezone and UTC. Row count (e.g. '12 rows') shows top-right. | F17: Medium | G17: Not Tested | K17: Live › Schedule Details
... A32: T2-LV-027 | B32: Live — Roster | C32: Keyboard Shortcuts dialog lists the documented shortcuts | D32: 1. Open the Keyboard Shortcuts dialog from the toolbar. 2. Read the grouped shortcut rows. 3. Test Ctrl+Q with flights selected. | E32: The dialog lists File Ctrl+S (Save all pending changes); Edit Ctrl+Z (Undo), Ctrl+Y (Redo), Del (Delete selected item), Esc (Clear selections / Close menu); Selection Click / Ctrl+Click; Pairing Ctrl+Q (Create Pairing from selected flights); View Ctrl++ / Ctrl+− (Zoom in/out). On macOS ⌘ replaces Ctrl; Redo also accepts Ctrl+Shift+Z and Delete also accepts Backspace. | F32: Low | G32: Not Tested | K32: Live › Keyboard shortcuts
A33: ▸ Scenario
A34: T2-SC-001 | B34: Scenario | C34: Scenario status lifecycle icons render for each state | D34: 1. Open the Scenario tab. 2. Inspect the status icon on scenario rows in the left list. 3. Confirm the icon-to-status mapping matches the documented lifecycle. | E34: Each status renders its documented icon: Pencil = Draft, spinning LoaderCircle = Running, CheckCircle2 = Done, AlertCircle = Failed, UploadCloud = Published. A sandbox scenario shows no effect on the live schedule until published. | F34: Medium | G34: Not Tested | K34: Scenario › Overview
A35: T2-SC-002 | B35: Scenario | C35: Search and Type/Status dropdowns filter the scenario list | D35: 1. Open the Scenario tab; confirm the left panel lists scenarios. 2. In the search bar (placeholder 'Search scenarios…'), type a known scenario ID or name and confirm the list narrows as you type. 3. Set the Type dropdown to 'RO' and confirm only RO scenarios remain. 4. Set the Status dropdown to 'Done' and confirm only Done scenarios remain. 5. Click a remaining row. | E35: The list live-filters by the typed text (ID/name/user); Type=RO shows only RO rows; Status=Done shows only Done rows; clicking a row opens that scenario's detail panel on the right. | F35: Medium | G35: Not Tested | K35: Scenario › Browsing and searching scenarios
A36: T2-SC-003 | B36: Scenario | C36: Create a new Draft scenario from a sidebar section | D36: 1. In the Scenario sidebar select the Roster section (for an RO scenario). 2. Click the + (Create new scenario) button at the top of the scenario list. 3. Confirm a new scenario is created immediately with Draft status and its detail panel opens on the right. 4. Verify the new scenario inherited the RO type of the section. | E36: A new scenario appears with Draft status (Pencil icon) and its editable detail panel opens on the right; the scenario type is RO, matching the Roster section it was created from. | F36: High | G36: Not Tested | K36: Scenario › Creating a new scenario
A37: T2-SC-004 | B37: Scenario | C37: Set RP Date and required fields, then Save a Draft scenario | D37: 1. Edit the Name field at the top of the detail panel to a descriptive value. 2. In Basic Info, choose a roster period with the RP Date selector. 3. Confirm the Start and End date inputs auto-fill from the selected period and are read-only. 4. Set Division, Rule Set, and Pairing Sc. (e.g. 0 - Live). 5. Click the Save icon (floppy disk) in the toolbar. | E37: Start/End populate read-only from the RP Date; after Save the icon shows a spinner then a success notification, and the scenario remains in Draft status. With no further edits the Save icon greys out with a 'Saved' tooltip. | F37: High | G37: Not Tested | K37: Scenario › Creating a new scenario
A38: T2-SC-005 | B38: Scenario | C38: Duplicate a scenario into a Draft copy retaining configuration | D38: 1. Hover the source scenario row and click the ⋯ menu button on the right. 2. Click Duplicate in the menu. 3. Confirm a new Draft named 'Copy of [original name]' is created and auto-selected with its detail panel open. 4. With the name field highlighted, type a new name and press Save (disk icon). | E38: A new Draft copy is created carrying the original type, date range, and type-specific config (Model, Rule Set, Pairing Scenario, Crew/Pairing scope filters) but no optimisation results or KPIs; the name field is auto-focused and the rename is saved. | F38: Medium | G38: Not Tested | K38: Scenario › Duplicating a scenario
A39: T2-SC-006 | B39: Scenario | C39: Start a PBS material import with a roster period and material selection | D39: 1. Click the Import PBS material button (Import icon) at the top of the scenario list panel. 2. In the Import PBS Material dialog, choose a Roster Period and confirm Start/End dates auto-fill read-only. 3. Tick at least one material type (Crew, Roster, RosterGround, Pairing, Flight). 4. Click Confirm. | E39: The import starts; the dialog shows overall progress (percent + elapsed time) and a per-material table with Fetch / Transform / Write stages showing Waiting/Running/Done/Failed status and timing. | F39: High | G39: Not Tested | K39: Scenario › Importing PBS material
A40: T2-SC-007 | B40: Scenario | C40: Review PBS import result counts on completion | D40: 1. Wait for the import to finish. 2. Review the result table for each selected material. 3. Check the completion toast. | E40: The result table shows each material's Status plus Add / Update / Delete / OK / Fail / Skip counts and Fetch / Trans / DB / Total timings; a success toast reports the imported connector count and elapsed time, or a warning lists how many materials failed if any did. | F40: High | G40: Not Tested | K40: Scenario › Importing PBS material
A41: T2-SC-008 | B41: Scenario | C41: Set PO Flight Filters scope on a PO scenario | D41: 1. Open the scenario's Scope Filters section and expand the Flight Filters group. 2. Add a flight number chip in Flight Nos (type a value, press Enter). 3. Add Dep Airports and/or Arr Airports and Fleets chips. 4. Set the Flight Status dropdown (Scheduled / Actual / All). 5. Click Save. | E41: Entered values appear as chips; the number badge on the Flight Filters header reflects the count of active filters; the Flight Status selection is applied; changes are saved. Empty fields mean 'include everything'. | F41: Medium | G41: Not Tested | K41: Scenario › Setting scope filters
A42: T2-SC-009 | B42: Scenario | C42: Set RO Crew and Pairing scope filters with live FILTER summaries | D42: 1. Open Scope Filters and expand the Crew Filters group. 2. Select Bases, Ranks, Fleets from their dropdowns and set a Seniority Min/Max range. 3. Expand the Pairing Filters group and select Bases, Ranks, Fleets, Type and a Duration (days) Min/Max range. 4. Observe the grey FILTER summary line under each group. 5. Click Save. | E42: Each group's number badge counts active filters; the FILTER line summarises Crew as bases/ranks/fleets/seniority/birthday and Pairing as bases/ranks/fleets/types/duration, with an asterisk (*) meaning no restriction; selections come from reference-table dropdowns and are saved. | F42: Medium | G42: Not Tested | K42: Scenario › Setting scope filters
A43: T2-SC-010 | B43: Scenario | C43: Pre-run check blocks an optimisation with missing required fields | D43: 1. Open the scenario with an incomplete required field. 2. Click the Play icon (Kick off run) in the scenario toolbar. 3. Review the Pre-run Check dialog. | E43: A Pre-run Check dialog opens listing the missing item(s) under 'Must fix before running' in red; the optimisation does not start. With warnings only (no blockers) a 'Proceed Anyway' button is offered instead. | F43: High | G43: Not Tested | K43: Scenario › Running an optimisation
A44: T2-SC-011 | B44: Scenario | C44: Save and run an optimisation to completion | D44: 1. Click the Play icon (Kick off run). 2. In the Unsaved changes dialog, choose Save & Run. 3. Confirm the 'Optimization started successfully' notification and that the toolbar button switches to the amber Stop icon. 4. Confirm the list status icon becomes a spinning Running icon and the detail badge reads Running. 5. Wait for the engine to finish. | E44: The run starts only after saving; while running the button shows the amber Stop icon and status is Running; on completion a success/failure notification appears and the status badge changes to Done (green CheckCircle2, results appear) or Failed (red AlertCircle). | F44: High | G44: Not Tested | K44: Scenario › Running an optimisation
A45: T2-SC-012 | B45: Scenario | C45: KPI, Credit Hours, and Uncovered result tabs show optimisation output | D45: 1. Open the Done scenario's detail panel and confirm the six-tab rail: KPI, Credit Hours, Uncovered, Distribution, Versions, Notes. 2. On the KPI tab, confirm one card per key metric (name, optimised value, description). 3. Open Credit Hours and confirm the per-crew table lists Crew Id, Base, Rank, Credited Hours, Credit Min/Max and related columns; use the search box and CSV export. 4. Open Uncovered and confirm the 'Uncovered Pairings & Reserves' table with row count. | E45: KPI shows one card per metric; Credit Hours lists per-crew credited hours with filter and CSV export; Uncovered lists unassigned pairing-complement rows (Pairing then Reserve) with a header row count, and is empty when everything is covered. | F45: High | G45: Not Tested | K45: Scenario › Reading your optimisation results
... A51: T2-SC-018 | B51: Scenario | C51: Delete a scenario with confirmation | D51: 1. Hover the target scenario row and click the ⋯ menu button. 2. Click Delete (trash icon) in the menu. 3. In the confirmation dialog, click Delete again to confirm. | E51: A confirmation dialog appears; after confirming, the scenario is permanently removed from the list along with all its settings, filters, and KPI results (the action cannot be undone). | F51: High | G51: Not Tested | K51: Scenario › Deleting a scenario
A52: ▸ Settings
A53: T2-SC-019 | B53: Settings | C53: Switch colour theme from the palette dropdown | D53: 1. Click the palette icon in the top-right corner of the navigation bar. 2. Confirm the dropdown lists the themes (Ocean Blue, Dark Pro, Emerald Green, Sunset Orange, Slate Gray) and shows the running version line (Ver:B…/F…/R…) at the top. 3. Click a theme other than the current one. | E53: The app colour scheme updates instantly without a page reload; a checkmark marks the newly selected theme; the version line at the top is informational only and does not change the applied theme. | F53: Low | G53: Not Tested | K53: Settings & Personalization › Changing the theme
A54: T2-SC-020 | B54: Settings | C54: Toggle dark/light mode independently of theme | D54: 1. Click the palette icon in the top-right corner to open the theme dropdown. 2. Click the Dark Mode / Light Mode toggle at the bottom of the dropdown. 3. Observe the app rendering and the toggle label. 4. Switch to the Dark Pro theme and observe the toggle behaviour. | E54: The app switches between dark and light rendering immediately and the label flips between Dark Mode/Light Mode; the choice is saved automatically; when Dark Pro is selected it always renders dark and the toggle has no effect. | F54: Low | G54: Not Tested | K54: Settings & Personalization › Switching dark / light mode
A55: T2-SC-021 | B55: Settings | C55: Sign out returns to the login screen | D55: 1. Hover the sign-out (door) icon in the top-right corner and confirm the 'Sign Out' tooltip. 2. Click the sign-out icon. | E55: The session ends immediately and the app redirects to the login screen; any unsaved Live changes would be lost (documented behaviour). Separately, after 60 minutes of inactivity a Session Timeout dialog with a 3-minute countdown appears and signs the user out if ignored. | F55: Low | G55: Not Tested | K55: Settings & Personalization › Signing out
A56: ▸ Regression
A57: T2-SC-022 | B57: Regression | C57: Create, generate, and run a plain-English regression test | D57: 1. Open the Regression tab; if the backend is unavailable confirm the 'Regression backend not available in this environment' message instead. 2. Click Add Test, enter a plain-English story, pick a category and priority, and save. 3. Click the wand button on the test row to generate Playwright code; if red issue chips appear, click Regenerate with fixes until gone, then Apply. 4. Click the category Run button (or Run All) and watch the bottom status bar progress. 5. Expand the row chevron to review Test story, Pass conditions, run outcome, and the evidence snapshot; on a failed round click Diagnose. | E57: The test is added and appears in the catalog; the wand generates Playwright code and blocks Apply until issue chips are cleared; running updates the status bar and records the result with a stability badge (Nx stable or N% fail) and an evidence snapshot; Diagnose returns an AI root-cause classification (code bug, data gap, environment issue, or test bug). | F57: Medium | G57: Not Tested | K57: Regression Playground › Overview & how to use

Sheet T3 Legality
A1: T3 — Legality (Rule Checks)
A2: UAT Round 1 • F8 (Flair) PBS • Reference: online help › Legality • crew-f8-usva-sit.roiscloud.com/altair/legality
A4: Test ID | B4: Feature | C4: What to Test | D4: How to Test (Steps) | E4: Expected Result | F4: Priority | G4: Result | H4: Tester | I4: Date Tested | J4: Comments / Screenshot | K4: Help Reference
A5: ▸ Legality — Admin
A6: T3-LG-001 | B6: Legality — Admin | C6: View violations against the active rule set in the Alert Center | D6: 1. Open the Live roster gantt with the F8 Full Ruleset enabled. 2. Confirm a warning bell marks the offending duty on the gantt. 3. Click the Alert Center bell button at the top-right of the roster pane (shows a violation count badge). 4. Read the list — one row per crew, rule and message; confirm each message begins with the triggering parameter row (e.g. 'Row 2:'). 5. Type a crew ID / rank / base into the search bar and confirm the group counts and table filter immediately. 6. Switch the grouping to Rule (then Severity / Base / Rank) and confirm rows regroup. 7. Click a violation row and confirm that crew is brought to the top of the Roster pane. | E6: Alert Center opens listing every violation for the loaded crew set; each row names the crew, the rule (e.g. 8002 Maximum Flight Time) and a message prefixed with the parameter Row number. Severity is colour-coded (red hard / amber overridable / yellow soft). Search and grouping update the list live; clicking a row scrolls that crew to the top. | F6: Medium | G6: Not Tested | K6: Legality › Overview
A7: T3-LG-002 | B7: Legality — Admin | C7: Create and enable a LIVE rule set and trigger a background recheck | D7: 1. In the Rule Sets header click the + (New) button. 2. In the New Rule Set dialog enter a Name, choose Division Pilot (P), and toggle at least the LIVE Rule Type on. 3. Tick 'Enable this rule set' and confirm the warning about clearing old legality alerts / starting a background recheck. 4. Save and confirm the new card appears in the sidebar with a blue LIVE badge, a P division badge, Enabled state, last-editor and rule count. 5. Confirm the previously enabled LIVE/P set is now Disabled (dimmed). 6. Use 'Add Rules' to add one catalog rule and confirm the set's rule count increments. | E7: The new set is created with the chosen name/division/type, becomes the active (highlighted) Enabled set for LIVE/P, the prior LIVE/P set is disabled, old legality alerts clear, and the affected roster period is re-checked in the background. Non-admins would see these controls hidden. | F7: Medium | G7: Not Tested | K7: Legality › Managing Rule Sets
A8: T3-LG-003 | B8: Legality — Admin | C8: Coverage warning flags a division + type with no enabled set | D8: 1. Disable every enabled set for one combination, e.g. all PBS sets for division Cabin (C). 2. Observe the Rule Sets header. 3. Hover the amber warning triangle that appears. 4. Re-enable a PBS/C set and confirm the warning clears. | E8: An amber warning triangle appears in the Rule Sets header while a LIVE/PBS division+type combination has no enabled set; hovering it lists the missing combination(s) (e.g. 'PBS/C'). Enabling a set for that combination removes the warning. | F8: Medium | G8: Not Tested | K8: Legality › Managing Rule Sets
A9: T3-LG-004 | B9: Legality — Admin | C9: Browse the rule catalog tree and copy a template to a new instance | D9: 1. Open Rule Templates from the sidebar (or use the Rule Instances tree on the Rule Sets view). 2. Expand the reference › category › function › instance hierarchy and confirm template instance-001 rows carry an amber star and a Template badge. 3. Type '8002' into 'Search rules…' and confirm matching branches auto-expand and hits highlight. 4. Click an instance and confirm its parameter table loads on the right. 5. Hover a template instance and click 'Copy to new instance'. 6. Confirm a new editable Copy (instance 001 of the same function) is created and its parameters can be edited independently. 7. Attempt 'Delete this instance' on a Template and on a rule used by a Rule Set. | E9: Catalog tree navigates the four-level hierarchy; search auto-expands/highlights; clicking an instance loads its Params table; Copy to new instance produces an independent editable copy. Delete is refused for Templates and for any rule used by a Rule Set. | F9: Medium | G9: Not Tested | K9: Legality › Rule Templates & Instances
A10: T3-LG-005 | B10: Legality — Admin | C10: Edit a rule parameter row, undo, save all and flag a recheck | D10: 1. Click a rule to expand its parameter table in place (Row column visible as 1,2,3…). 2. Click the Edit row pencil in the Actions column; the row turns amber and cells validate their own format. 3. Change a threshold (e.g. lower Max Limits) and click ✓ (enabled only when every cell is valid). 4. Use Copy row, then Move up / Move down, then Add Row and Delete row (confirm 'Yes, delete'). 5. In the Changes panel confirm each EDIT / COPY / MOVE / ADD / DEL action is logged newest-first; click ⟲ Undo once and confirm the last change reverts. 6. Click Save All and wait for 'Saving…' → 'Parameters saved'. | E10: Row edits validate per-cell and only commit on ✓; Changes panel logs every action with Undo working; nothing persists until Save All. After Save All the parameters are written to the rule set and the affected rosters are flagged for a legality recheck (live check auto re-runs). Without admin rights the Actions column, Add Row and Save All are hidden and the table is read-only. | F10: High | G10: Not Tested | K10: Legality › Editing rule parameters (admin)
A11: ▸ Legality — Rule
A12: T3-LG-006 | B12: Legality — Rule | C12: 1001 Assignment Overlap fires when a Before and After duty overlap in time | D12: 1. Assign the crew a FLY duty. 2. Assign a second activity (a day off DO, or an L|O type) whose time window overlaps the FLY duty end (Rest Before = Y tests against duty end). 3. Recheck legality and open the Alert Center. 4. Repeat with the second activity moved so it does NOT overlap the duty window. | E12: Overlapping case raises a 1001 Assignment Overlap violation naming the prohibited Before → After combination (e.g. FLY → DO). The non-overlapping rest-only day off / leave stays Allowed with no 1001 violation. | F12: High | G12: Not Tested | K12: Legality › 1001 — Assignment Overlap
A13: T3-LG-007 | B13: Legality — Rule | C13: 2014 Local Night Definition raises no violation but supplies the local-night window downstream | D13: 1. Open rule 2014 and confirm the 'No violations' chip / definition note. 2. Confirm no Alert Center row is ever attributed to 2014 itself. 3. As admin change Local Night Start/End and Min Interval Hours, Save All and recheck. 4. Observe day-off/WOCL rules that consume it (7501 Single Day Free, 7503/7504 WOCL) recompute their single-day/local-night boundaries. | E13: Rule 2014 never produces its own violation. Changing its window shifts the local-night boundary used by 7501 and the WOCL run reset in 7503/7504, changing those rules' results — proving 2014 feeds downstream rather than firing itself. | F13: High | G13: Not Tested | K13: Legality › 2014 — Local Night Definition
A14: T3-LG-008 | B14: Legality — Rule | C14: 7272 Reserve DP raises no violation but charges reserve/standby duty period downstream | D14: 1. Open rule 7272 and confirm the 'No violations' chip. 2. Assign a crew a reserve/standby block (SBY) that carries no flight segments. 3. Recheck and confirm no Alert Center row is attributed to 7272 itself. 4. Inspect 8002 Maximum Hours of Work for the same crew and confirm the standby block contributes a charged duty period (≈ Rate 0.33 of the standby window). | E14: Rule 7272 produces no violation of its own; it assigns the reserve/standby block a duty-period value that 8002 Maximum Hours of Work counts. Lowering the Rate reduces the duty charged to the cumulative duty-hour rule. | F14: High | G14: Not Tested | K14: Legality › 7272 — Calculate DP of the Reserves
A15: T3-LG-009 | B15: Legality — Rule | C15: 7500 Acc State raises no violation but supplies the acclimatized time zone downstream | D15: 1. Open rule 7500 and confirm the 'No violations' chip / definition note. 2. Recheck legality and confirm no Alert Center row is attributed to 7500 itself. 3. Give a crew duty in a distant time zone and confirm the WOCL rules 7503/7504 read local time at the acclimatized (base) zone this rule produces. | E15: Rule 7500 never fires; it produces each crew's acclimatized reference time zone (base-zone fallback) that the WOCL rules 7503/7504 consume to read 02:00–05:59 local time. No violation is ever labelled 7500. | F15: High | G15: Not Tested | K15: Legality › 7500 — Basic definition of Acc State
A16: T3-LG-010 | B16: Legality — Rule | C16: 7501 Single Day Free from Duty fires when too few single days free fall in a rolling window | D16: 1. Build a roster where a crew has fewer than the required single days free from duty inside a rolling 168-hour window (below the demo minimum of 3). 2. Recheck legality and open the Alert Center. 3. Adjust the roster to insert enough single days free (≥3 in 168h and ≥4 in 672h) and recheck. | E16: Under-provisioned window raises a 7501 Single Day Free from Duty in Rolling Hours violation (message prefixed with the parameter Row, e.g. the 168 RH row). When the required single days free are provided in both the 168h and 672h windows, no 7501 violation appears. | F16: High | G16: Not Tested | K16: Legality › 7501 — Single Day Free from Duty in Rolling Hours
A17: T3-LG-011 | B17: Legality — Rule | C17: 7502 Credit Hours raises no violation but feeds the monthly credit-hour band | D17: 1. Open rule 7502 and confirm the 'No violations' chip. 2. Assign a crew a mix of FLY, GND and DO/leave days and recheck. 3. Confirm no Alert Center row is attributed to 7502 itself. 4. Inspect the 8002 Maximum Flight Time monthly credit-hour band (Type CH) and confirm it reconciles against the credit values 7502 derives. | E17: Rule 7502 never fires; it computes each assignment's credit hours (min-floor / flight hours / duty ratio) that the 8002 monthly credit-hour band (CH 65:00–75:00 demo) reads. No violation is labelled 7502. | F17: High | G17: Not Tested | K17: Legality › 7502 — The Calculation of Credit Hours
A18: T3-LG-012 | B18: Legality — Rule | C18: 7503 Limits of Consecutive WOCLs fires when consecutive WOCL duties exceed the cap | D18: 1. Assign a crew 3 consecutive duties each touching 02:00–05:59 acclimatized, with no local night's rest resetting the run (exceeds the demo cap of 2). 2. Recheck legality and open the Alert Center. 3. Reduce to 2 consecutive WOCL duties (or insert a local night's rest to reset the run) and recheck. | E18: Exceeding the Max Consecutive WOCLs cap raises a 7503 Limits of Consecutive WOCLs violation. Within the cap (or with a local night's rest breaking the run) no 7503 violation appears. | F18: High | G18: Not Tested | K18: Legality › 7503 — Limits of Consecutive WOCLs
A19: T3-LG-013 | B19: Legality — Rule | C19: 7504 Spacing Rule – WOCL fires when two WOCL flight duties are spaced under the minimum | D19: 1. Assign a crew two flight duties that each touch the WOCL (02:00–05:59), spaced less than the demo minimum of 80 rolling hours apart. 2. Recheck legality and open the Alert Center. 3. Move the second WOCL flight duty so the gap is ≥80 RH and recheck. | E19: Spacing below the Min Period raises a 7504 Spacing Rule - WOCL violation between the two WOCL flight duties. When the two WOCL duties are ≥ the minimum spacing apart, no 7504 violation appears (other duties may sit in the gap). | F19: High | G19: Not Tested | K19: Legality › 7504 — Spacing Rule - WOCL
A20: T3-LG-014 | B20: Legality — Rule | C20: 7505 Min # GDOs in a RP fires when guaranteed days off fall below the sliding minimum | D20: 1. Select a 31-day roster period and a crew with 0 vacation days (row requires 13 Min DO). 2. Assign enough duty so the crew has fewer than 13 days off (DO group) in the period. 3. Recheck legality and open the Alert Center. 4. Free up days so the crew has ≥13 GDOs (or add vacation so the required minimum slides down below the actual count) and recheck. | E20: Below the row's Min DO (13 for a 31-day month, 0 vacation) raises a 7505 Min # GDOs in a RP violation. When GDOs meet or exceed the sliding minimum for the matched month-length/vacation band, no 7505 violation appears. | F20: High | G20: Not Tested | K20: Legality › 7505 — Min # GDOs in a RP
A21: T3-LG-015 | B21: Legality — Rule | C21: 7506 One Check-in Per Day fires on a second flight report the same calendar day | D21: 1. Assign a crew two separate FLY duties that each require a report (check-in) on the same calendar day. 2. Recheck legality and open the Alert Center. 3. Move the second FLY duty's report to the next calendar day and recheck. | E21: Two reports on the same calendar day raise a 7506 One Check-in Per Day violation. When the two reports fall on different calendar days, no 7506 violation appears. | F21: High | G21: Not Tested | K21: Legality › 7506 — One Checkin Per Day
A22: T3-LG-016 | B22: Legality — Rule | C22: 7507 Min # GDOs with fly/reserve filters fires when GDOs fall below the min for the matching band | D22: 1. Build a roster for a crew whose fly-day and reserve-day counts fall inside a specific NUM FLY DAY / NUM RESERVES band row. 2. Assign duty so days off drop below that row's Min DO. 3. Recheck legality and open the Alert Center. 4. Add days off so GDOs meet the row's Min DO (or change fly/reserve counts so a more lenient band row matches) and recheck. | E22: When the crew's fly-day/reserve-day counts match a band row and GDOs are below that row's Min DO, a 7507 Min # GDOs violation fires. Meeting the Min DO for the matched fly/reserve band clears it; a crew whose counts match no band (or * filters) is not constrained by that row. | F22: High | G22: Not Tested | K22: Legality › 7507 — Min # GDOs (fly/reserve filters)
A23: T3-LG-017 | B23: Legality — Rule | C23: 8002 Maximum Flight Time fires when cumulative block hours exceed the rolling-window cap | D23: 1. Assign a crew flight duties whose cumulative block (flight) hours in the rolling 28-day window exceed the 40:00 demo Max Limit. 2. Recheck legality and open the Alert Center. 3. Separately, drive the calendar-month credit hours outside the 65:00–75:00 band. 4. Reduce block hours below 40:00 in every rolling window and bring credit hours inside 65–75, then recheck. | E23: Block hours over a window's Max Limit raise an 8002 Maximum Flight Time violation (message names the offending Row/window, e.g. the 28-day row). Credit hours outside the monthly Min/Max band trigger the standalone credit-hour-utilisation row. Within every window's limit and inside the credit band, no 8002 flight-time violation appears. | F23: High | G23: Not Tested | K23: Legality › 8002 — Maximum Flight Time
... A27: T3-LG-021 | B27: Legality — Rule | C27: 8056 Roster Spacing fires when two qualifying duties are scheduled under the minimum gap | D27: 1. Assign a crew a flight duty (A) followed by a flight/standby/simulator duty (B) spaced less than the demo minimum of 24 rolling hours apart. 2. Recheck legality and open the Alert Center. 3. Increase the gap between A and B to ≥24 RH and recheck. | E27: A FLY → FLY|SBY|SIM pair closer than the Space minimum raises an 8056 Roster Spacing violation. When the two qualifying duties are spaced at least the minimum apart, no 8056 violation appears. | F27: High | G27: Not Tested | K27: Legality › 8056 — Roster Spacing

Sheet T4 Crew Portal
A1: T4 — Crew Portal (Crew Bidding App)
A2: UAT Round 1 • F8 (Flair) PBS • Reference: online help • crew-f8-usva-sit.roiscloud.com/pbs/help
A4: Test ID | B4: Feature | C4: What to Test | D4: How to Test (Steps) | E4: Expected Result | F4: Priority | G4: Result | H4: Tester | I4: Date Tested | J4: Comments / Screenshot | K4: Help Reference
A5: ▸ Quick Start
A6: T4-CP-001 | B6: Quick Start | C6: Portal top navigation exposes all bidding pages | D6: 1. Log in to PBS Portal. 2. Read the top navigation. 3. Open each page in turn: Dashboard, Bid, Reserve, Standing Bid, Award, Help. | E6: All six pages are reachable from navigation: Dashboard shows bid period/profile/calendar, Bid holds Days Off/Pairing/Roster conditions, Reserve holds Reserve Preference, Standing Bid holds reusable conditions, Award shows published results, and Help returns to the manual. | F6: Low | G6: Not Tested | K6: Quick Start › PBS Portal overview
A7: T4-CP-002 | B7: Quick Start | C7: Confirm bid-period context before adding a condition | D7: 1. Open Dashboard and confirm the crew name and employee information for the active session. 2. Read BID INFORMATION-LOCAL TIME and note bid start, bid end, and remaining time. 3. Confirm the month shown in BIDDING CALENDAR. 4. Decide whether the condition belongs to Current Bid or should be a reusable Standing Bid. | E7: Identity, BID START/BID END/REMAINING, and calendar month are all displayed; crew can distinguish Current Bid from Standing Bid before proceeding to Bid, Reserve, or Standing Bid. | F7: Low | G7: Not Tested | K7: Quick Start › Before you begin
A8: T4-CP-003 | B8: Quick Start | C8: Complete the basic bidding flow and save a Current Bid condition | D8: 1. Open Dashboard and confirm the active bid period and calendar month. 2. Open Bid; under ADD BID PROPERTIES select DAYS OFF. 3. Select a property, complete its required fields, and choose one or more T1-T7 buttons. 4. Select ADD BID and keep the dialog open while the button shows the pending state. 5. Confirm the new condition appears under EXISTING BID PROPERTIES. | E8: A saved row appears in EXISTING BID PROPERTIES with its category badge, condition summary, and Tier tags, confirming the condition is part of the Current Bid. | F8: High | G8: Not Tested | K8: Quick Start › Complete a Bid
A9: T4-CP-004 | B9: Quick Start | C9: View the published Award at the end of the bidding flow | D9: 1. Open Award after results are published. 2. Review the awarded roster and the duty blocks on the calendar. 3. Select a duty to review its details. | E9: Award shows the published roster and duty details for the period; the crew understands an Award is a result view produced only after publication, not immediately when a bid is saved. | F9: Medium | G9: Not Tested | K9: Quick Start › Complete a Bid
A10: ▸ Dashboard
A11: T4-CP-005 | B11: Dashboard | C11: Dashboard shows active bid-period context | D11: 1. Open Dashboard. 2. Confirm identity/contact in the left panel. 3. Read BID INFORMATION-LOCAL TIME (BID START, BID END, REMAINING). 4. Confirm the month in BIDDING CALENDAR and review MESSAGE CENTER pre-assigned duties. | E11: Dashboard displays profile, bid window with start/end/remaining, current calendar month, and the MESSAGE CENTER pre-assigned duties panel; no fleet or sub-fleet pool counts are shown. | F11: Low | G11: Not Tested | K11: Dashboard › Overview
A12: T4-CP-006 | B12: Dashboard | C12: Verify crew identity and USER INFORMATION fields | D12: 1. Open Dashboard and read the avatar, name, and email at the top of the left panel. 2. In BID INFORMATION-LOCAL TIME confirm the bid window; in REMAINING confirm the coarse time left. 3. In USER INFORMATION read BASE, FLEET, POSITION, SENIORITY, LANGUAGE, EXISTING CREDIT, TRAINING MONTH, and LAST LOGIN. | E12: The active user is confirmed as the expected crew member; USER INFORMATION shows all profile fields (a dash where no value returned); the panel is read-only and REMAINING shows days/hours only, or Closed for a closed window. | F12: Low | G12: Not Tested | K12: Dashboard › User and bid information
A13: T4-CP-007 | B13: Dashboard | C13: Read BIDDING CALENDAR tiers, activity colors, and Days Off capacity badge | D13: 1. Confirm the month label and weekday headings above the grid. 2. Read the T1-T7 rows and identify the highlighted active Tier. 3. Review colored entries in date cells (green Days Off/Prefer Off, blue Pairing, yellow warning). 4. Read the Days Off capacity badge at the bottom of a date cell, such as 23/33. | E13: The calendar shows the active-Tier highlight, color-coded saved activity, and a requested/max capacity badge that is green when requested is below max, yellow when equal, and red when above max. | F13: Medium | G13: Not Tested | K13: Dashboard › Read the bidding calendar
A14: T4-CP-008 | B14: Dashboard | C14: Read MESSAGE CENTER pre-assigned duty counts and details | D14: 1. Open Dashboard and find MESSAGE CENTER on the right. 2. Read Pre-assigned Duties totals and Covered days. 3. Read the type rows (Pairing, Days Off, Reserve, Training, Deadhead, Unavailable, Other). 4. Scroll Duty Details and read a duty's label, date range, type tag, and time. | E14: MESSAGE CENTER shows total duties, covered days, per-type counts with matching calendar colors, and a scrollable Duty Details list; the panel is read-only and is shown independently of whether an Award has been published. | F14: Low | G14: Not Tested | K14: Dashboard › Pre-assigned duties
A15: ▸ Bid
A16: T4-CP-009 | B16: Bid | C16: Bid workspace holds Days Off, Pairing, and Roster in one Existing list | D16: 1. Open Bid. 2. Review EXISTING BID PROPERTIES and the Pairing toolbar (REFRESH, VIEW RULES, SEARCH PAIRINGS). 3. Open ADD BID PROPERTIES and confirm FAVORITED PROPERTIES, DAYS OFF, PAIRING, and ROSTER are available. 4. Type into Search Bid Properties. | E16: Bid shows one shared EXISTING BID PROPERTIES list for the active Tier, the Pairing toolbar actions, and the ADD BID PROPERTIES categories; Search Bid Properties filters the property list within the selected category. | F16: Low | G16: Not Tested | K16: Bid › Overview
A17: T4-CP-010 | B17: Bid | C17: Select a Tier and read Days Off capacity in BIDDING CALENDAR | D17: 1. In BIDDING CALENDAR read the Current period status (open + time remaining) and Month. 2. Select a T1-T7 tier to set the active Current Bid Tier. 3. Read a date cell Days Off capacity badge such as 23/33. 4. Note the badge color relative to the max. | E17: The selected tier becomes the active Current Bid context, the heatmap summarizes activity for that tier, and the capacity badge shows requested/max with green below max, yellow equal, red above max (guidance only, not an Award guarantee). | F17: Medium | G17: Not Tested | K17: Bid › Use the bidding calendar
A18: T4-CP-011 | B18: Bid | C18: Request Days Off by weekday and collapse the calendar | D18: 1. Select a T1-T7 tier. 2. Select a weekday heading to request Days Off on the matching dates in the displayed month. 3. Confirm the saved activity appears on those dates. 4. Use the left arrow to collapse the calendar, then the calendar button to expand it again. | E18: The weekday action creates Days Off requests on the matching dates and the calendar plus related Current Bid view refresh with the saved change; the collapse/expand choice is remembered in the browser. | F18: Medium | G18: Not Tested | K18: Bid › Use the bidding calendar
A19: T4-CP-012 | B19: Bid | C19: Add a Days Off Current Bid condition from ADD BID PROPERTIES | D19: 1. Open Bid and review EXISTING BID PROPERTIES for similar conditions. 2. Under ADD BID PROPERTIES select DAYS OFF. 3. Optionally filter with Search Bid Properties, then select the add button on a property row. 4. Complete every REQUIRED section and select one or more T1-T7 buttons. 5. Select ADD BID and wait for the save to finish. | E19: After the server confirms, a new Days Off row appears under EXISTING BID PROPERTIES with its category, summary, and Tier tags; if ADD BID stays unavailable, required fields or a missing Tier are the cause. | F19: High | G19: Not Tested | K19: Bid › Add Bid properties
A20: T4-CP-013 | B20: Bid | C20: Add a Roster (Mixed Line Bid) condition | D20: 1. Under ADD BID PROPERTIES select ROSTER. 2. Select Mixed Line Bid and open its Configure dialog. 3. Choose Reserve Only or Pairing Only (Mixed Line is the default and saves no 427 bid). 4. Select at least one T1-T7 and select ADD BID. | E20: A Reserve Only or Pairing Only roster condition is saved under EXISTING BID PROPERTIES; choosing the default Mixed Line saves no 427 bid. | F20: High | G20: Not Tested | K20: Bid › Add Bid properties
A21: T4-CP-014 | B21: Bid | C21: Configure Pairing Preference by searching and selecting pairing rows | D21: 1. From ADD PAIRING PROPERTIES select Pairing Preference to open Configure Pairing Bid. 2. Select the active TIERS (at least one). 3. Choose MODE (Award or Avoid) and QUANTIFIER (Any or Every) when shown. 4. Use the search box to narrow the pairing list by pairing number, base, route, or rank text. 5. Select one or more pairing rows and confirm the selected count/chips. 6. Select ADD BID. | E21: ADD BID stays disabled until at least one pairing row is selected; after saving, a Pairing Preference row appears in EXISTING PAIRING PROPERTIES reflecting the selected pairings, mode, and tiers. | F21: High | G21: Not Tested | K21: Bid › Configure Pairing Preference
A22: T4-CP-015 | B22: Bid | C22: Narrow the pairing list with Pairing Filters before saving | D22: 1. In the pairing list click Filters to open Pairing Filters. 2. Set conditions such as Pairing start dates, Check-in/Check-out, Length, Route station, Credit, or Redeye/DHD. 3. Click Apply Filters. 4. Select the matching pairing rows, then click ADD BID. | E22: Pairing Filters narrow the selectable list only (they do not save a bid); the saved bid comes from the selected rows, and Clear All resets filter fields without saving. | F22: High | G22: Not Tested | K22: Bid › Configure Pairing Preference
A23: T4-CP-016 | B23: Bid | C23: Preview, edit, and delete a saved Current Bid condition | D23: 1. Set the active Tier in BIDDING CALENDAR to match the condition. 2. Read the category badge, summary, and Tier tags in EXISTING BID PROPERTIES. 3. Select PREVIEW on a supported Pairing row to see matching evidence. 4. Select EDIT, change required fields or Tier selection, and select UPDATE BID. 5. Use the delete button and confirm the row no longer appears. | E23: The Existing list and summary refresh after a successful update or delete; a condition assigned only to another Tier is absent from the current Tier view (change the active Tier before deciding it is missing). | F23: High | G23: Not Tested | K23: Bid › Review, edit, and delete
A24: T4-CP-017 | B24: Bid | C24: Reuse a Favorite and search matching pairings | D24: 1. Open FAVORITED PROPERTIES under ADD BID PROPERTIES. 2. Select a Favorite, review its condition, and choose one or more SELECT TX buttons. 3. Select ADD TO BID and confirm the new row under EXISTING BID PROPERTIES. 4. Select VIEW RULES to review active rules, or SEARCH PAIRINGS to search with current rules (ALL PAIRINGS to browse unfiltered). | E24: Adding a Favorite creates a new Existing Bid row with the chosen tiers; SEARCH PAIRINGS returns pairings matching the active rules; updating a Favorite changes only the template, not previously created Existing rows. | F24: Medium | G24: Not Tested | K24: Bid › Favorites and Search Pairings
A25: ▸ Reserve
A26: T4-CP-018 | B26: Reserve | C26: Reserve page combines Reserve Preference with the coverage calendar | D26: 1. Open Reserve. 2. Locate ADD RESERVE PREFERENCE, RESERVE COVERAGE, and EXISTING RESERVE PROPERTIES. 3. Read the Need and Off values on a coverage date. | E26: Reserve shows RESERVE PREFERENCE as the only Current Reserve condition, the coverage calendar with per-date Need/Off, and the EXISTING RESERVE PROPERTIES list with tier assignments; reusable reserve conditions are maintained separately in Standing Bid. | F26: Low | G26: Not Tested | K26: Reserve › Overview
A27: T4-CP-019 | B27: Reserve | C27: Add a Reserve Preference with short-call type, date scope, and tiers | D27: 1. Open Reserve and review RESERVE COVERAGE. 2. Select ADD RESERVE PREFERENCE. 3. In Configure Reserve Preference choose SHORT-CALL TYPE (e.g. PRAM). 4. Choose DATE SCOPE and complete any required date fields. 5. Select one or more T1-T7 under APPLY TO TIERS and select ADD BID. | E27: A saved row appears under EXISTING RESERVE PROPERTIES with the selected short-call type, date scope, and tier assignment; if ADD BID is unavailable, SHORT-CALL TYPE, DATE SCOPE, or APPLY TO TIERS is incomplete. | F27: High | G27: Not Tested | K27: Reserve › Add and manage Reserve Preference
A28: T4-CP-020 | B28: Reserve | C28: Edit and delete an existing Reserve Preference row | D28: 1. In EXISTING RESERVE PROPERTIES locate the row. 2. Use its edit action, change the short-call type, date scope, or tiers, and confirm. 3. Use the delete action on a row and wait for the save to finish. | E28: The edited row reflects the updated short-call type/date scope/tiers, and the deleted row is removed from EXISTING RESERVE PROPERTIES after the draft updates. | F28: High | G28: Not Tested | K28: Reserve › Add and manage Reserve Preference
A29: T4-CP-021 | B29: Reserve | C29: Duplicate Reserve Preference combination is warned, not duplicated | D29: 1. Select ADD RESERVE PREFERENCE. 2. Choose the same SHORT-CALL TYPE, DATE SCOPE, and APPLY TO TIERS as an existing row. 3. Select ADD BID. | E29: The Portal shows a duplicate warning instead of creating a second identical row; EXISTING RESERVE PROPERTIES still contains only the original row. | F29: High | G29: Not Tested | K29: Reserve › Add Reserve Preference (duplicate guard)
A30: T4-CP-022 | B30: Reserve | C30: Open Configure Reserve Preference from a coverage date | D30: 1. Review RESERVE COVERAGE and read a date's Need and Off counts. 2. Click a date cell to open Configure Reserve Preference with that date prefilled under Specific Dates. 3. Select T1-T7 under APPLY TO TIERS, review SHORT-CALL TYPE, and click ADD BID. | E30: The clicked date opens Reserve Preference (not Reserve Day On or Prefer Off) with the date under Specific Dates; the bid saves only after tiers are chosen and ADD BID confirmed, then appears in existing reserve properties. | F30: Medium | G30: Not Tested | K30: Reserve › Reserve coverage calendar
A31: T4-CP-023 | B31: Reserve | C31: Current Reserve exposes only Reserve Preference, no mode switch | D31: 1. Open the Reserve page. 2. Confirm there is no Reserve mode switch (Legacy Reserve / AA Prefer Off are not shown). 3. Use ADD RESERVE PREFERENCE or click a coverage date, then configure short-call type, tiers, and date scope. | E31: Current Reserve always saves Reserve Preference rows with no employee-facing mode selector; reserve avoidance is handled from Line via Reserve Avoidance, not this page. | F31: Low | G31: Not Tested | K31: Reserve › Current Reserve workflow
A32: T4-CP-024 | B32: Reserve | C32: Configure Reserve Preference date-scope options | D32: 1. Click ADD RESERVE PREFERENCE and choose SHORT-CALL TYPE. 2. Under APPLY TO TIERS select one or more T1-T7 checkboxes. 3. Under DATE SCOPE choose Whole Month, First Half, Second Half, Date Range, or Specific Dates. 4. For Date Range set from/to dates (end same or later than start); for Specific Dates use the date input and ADD DATE. 5. Click ADD BID. | E32: The Reserve Preference row is added with the chosen date scope attached to the short-call type; Current Reserve allows exact ranges/specific dates while Standing Reserve allows only Whole Month/First Half/Second Half. | F32: High | G32: Not Tested | K32: Reserve › Configure short-call type and date scope
A33: ▸ Days Off
A34: T4-CP-025 | B34: Days Off | C34: Days Off page shows existing and addable properties | D34: 1. Open Days Off from the top navigation. 2. Review EXISTING DAYS OFF PROPERTIES (PROPERTY, BID, TIERS columns). 3. Open ADD DAYS OFF PROPERTIES and confirm ALL PROPERTIES, FAVORITED PROPERTIES, and Search Properties. | E34: Days Off shows the existing saved rows with PROPERTY/BID/TIERS columns and the ADD DAYS OFF PROPERTIES catalog with tabs and search; add/update/delete actions call the Days Off draft service and refresh the calendar and Bid review. | F34: Low | G34: Not Tested | K34: Days Off › Overview
A35: T4-CP-026 | B35: Days Off | C35: Add a specific-date Days Off bid from the right panel | D35: 1. Open Days Off and keep ALL PROPERTIES selected in ADD DAYS OFF PROPERTIES. 2. Optionally type into Search Properties to filter by property name. 3. Click the add action beside a date-based property to open Configure Days Off Bid. 4. Select at least one tier under TIERS, add a date via DATES/ADD DATE, then click ADD BID. | E35: The new row appears in EXISTING DAYS OFF PROPERTIES immediately after the draft service saves it; the related calendar and Bid review data refresh. | F35: High | G35: Not Tested | K35: Days Off › Add Days Off properties
A36: T4-CP-027 | B36: Days Off | C36: Add a Days Off bid using DAYS OF WEEK or DATE RANGE | D36: 1. Open Configure Days Off Bid for a property. 2. Select at least one tier under TIERS. 3. Choose DAYS OF WEEK for recurring weekday preferences, or DATE RANGE for a continuous range (end date same or later than start). 4. Click ADD BID. | E36: ADD BID saves only with a valid tier and a valid date/weekday/date range; an invalid range (end before start) is rejected, and the saved recurring or range bid appears in EXISTING DAYS OFF PROPERTIES. | F36: High | G36: Not Tested | K36: Days Off › Add Days Off properties
A37: T4-CP-028 | B37: Days Off | C37: Verify tier context and capacity before adding a Days Off bid | D37: 1. Select the T1-T7 tier context to work with. 2. Use the Dashboard or shared calendar to review existing days-off and pairing activity. 3. Read the requested/max capacity badge such as 23/33 for a target date. 4. Save a Days Off action, then verify EXISTING DAYS OFF PROPERTIES shows the expected TIERS. | E37: The saved row carries the active tier; the capacity badge (green below max, yellow equal, red above max) reflects crew request counts (same crew counted once per date across tiers) and is a planning signal, not an Award guarantee. | F37: Medium | G37: Not Tested | K37: Days Off › Calendar and tier context
A38: T4-CP-029 | B38: Days Off | C38: Edit and delete an existing Days Off row | D38: 1. Find the row in EXISTING DAYS OFF PROPERTIES and read PROPERTY, BID, and TIERS. 2. Click the edit action to reopen Configure Days Off Bid with saved values. 3. Change dates, days, time window, modifiers, or tiers and click UPDATE BID. 4. On another row click the delete action and wait for the save to finish. | E38: The edited row updates in place and the deleted row disappears from EXISTING DAYS OFF PROPERTIES; the bidding calendar and Bid review refresh, and any save conflict prompts a draft reload. | F38: High | G38: Not Tested | K38: Days Off › Review, edit, and delete
A39: T4-CP-030 | B39: Days Off | C39: Save and reuse a Days Off favorite template | D39: 1. Add/edit a Days Off property until the dialog has the dates, days, time window, modifiers, and tiers to reuse. 2. Click SAVE FAVORITE. 3. Open FAVORITED PROPERTIES in ADD DAYS OFF PROPERTIES. 4. Click the add action on the favorite row. | E39: The favorite is stored as a reusable template and adding it copies the configuration into the current draft as a new Existing row; removing a favorite deletes only the template, not an already-saved draft row. | F39: Medium | G39: Not Tested | K39: Days Off › Favorites
A40: ▸ Pairing
A41: T4-CP-031 | B41: Pairing | C41: Pairing workspace shows rows, counts, rules, and Search Pairings | D41: 1. Open Pairing. 2. Review EXISTING PAIRING PROPERTIES (PROPERTY, BID, TIERS, COUNT). 3. Read the pool-count toolbar (current tier, rule count, pairing result count, REFRESH, VIEW RULES/VIEW PROPERTIES, SEARCH PAIRINGS). 4. Open ADD PAIRING PROPERTIES. | E41: Pairing shows the existing rows with a COUNT column, the pool-count toolbar with refresh/rules/search actions, and the add catalog; changes save to the current draft and may leave pool counts stale until refreshed. | F41: Low | G41: Not Tested | K41: Pairing › Overview
...
